Workbook

Sheet 栽培スケジュール
A1: #作付 | B1: #品目 | C1: 野菜名 | D1: 所得（千円） | E1: 粗収益 | F1: 経営費(減価償却費除く) | G1: 経営費率 | H1: 総労働時間(h) | I1: 時給(円/h) | J1: 休栽年数 | K1: 4 | L1: 5 | M1: 6 | N1: 7 | O1: 8 | P1: 9 | Q1: 10 | R1: 11 | S1: 12 | T1: 1 | U1: 2 | V1: 3 | W1: s(h) | X1: o(h) | Y1: f(h) | Z1: 粗収益/月 | AA1: 経営費/月
A2: 50a | B2: 50 | C2: ヘチマ | D2: 440 | E2: 767.88831 | F2: 327.88831 | G2: 0.427 | H2: 652 | I2: 674.84663 | J2: 2 | K2: s | L2: o | M2: o | N2: f | O2: f | P2: f | V2: s | W2: 48.9 | X2: 65.2 | Y2: 141.26667 | Z2: 255.96277 | AA2: 163.94415
A3: 50b | B3: 50 | C3: ヘチマ | D3: 440 | E3: 767.88831 | F3: 327.88831 | G3: 0.427 | H3: 652 | I3: 674.84663 | J3: 2 | K3: s | L3: s | M3: o | N3: o | O3: f | P3: f | Q3: f | W3: 48.9 | X3: 65.2 | Y3: 141.26667 | Z3: 255.96277 | AA3: 163.94415
A4: 51a | B4: 51 | C4: かぼちゃ | D4: 158 | E4: 364.0553 | F4: 206.0553 | G4: 0.566 | H4: 115 | I4: 1373.913 | J4: 1 | P4: s | Q4: s | R4: o | S4: o | T4: f | U4: f | W4: 8.625 | X4: 11.5 | Y4: 37.375 | Z4: 182.02765 | AA4: 103.02765
A5: 51b | B5: 51 | C5: かぼちゃ | D5: 158 | E5: 364.0553 | F5: 206.0553 | G5: 0.566 | H5: 115 | I5: 1373.913 | J5: 1 | Q5: s | R5: s | S5: o | T5: o | U5: f | V5: f | W5: 8.625 | X5: 11.5 | Y5: 37.375 | Z5: 182.02765 | AA5: 103.02765
A6: 51c | B6: 51 | C6: かぼちゃ | D6: 158 | E6: 364.0553 | F6: 206.0553 | G6: 0.566 | H6: 115 | I6: 1373.913 | J6: 1 | K6: f | R6: s | S6: s | T6: o | U6: o | V6: f | W6: 8.625 | X6: 11.5 | Y6: 37.375 | Z6: 182.02765 | AA6: 103.02765
A7: 51d | B7: 51 | C7: かぼちゃ | D7: 158 | E7: 364.0553 | F7: 206.0553 | G7: 0.566 | H7: 115 | I7: 1373.913 | J7: 1 | K7: f | L7: f | T7: s | U7: s | V7: o | W7: 8.625 | X7: 23 | Y7: 37.375 | Z7: 182.02765 | AA7: 103.02765
A8: 51e | B8: 51 | C8: かぼちゃ | D8: 158 | E8: 364.0553 | F8: 206.0553 | G8: 0.566 | H8: 115 | I8: 1373.913 | J8: 1 | K8: o | L8: f | M8: f | U8: s | V8: s | W8: 8.625 | X8: 23 | Y8: 37.375 | Z8: 182.02765 | AA8: 103.02765
A9: 51f | B9: 51 | C9: かぼちゃ | D9: 158 | E9: 364.0553 | F9: 206.0553 | G9: 0.566 | H9: 115 | I9: 1373.913 | J9: 1 | K9: s | L9: o | M9: f | N9: f | V9: s | W9: 8.625 | X9: 23 | Y9: 37.375 | Z9: 182.02765 | AA9: 103.02765
A10: 51g | B10: 51 | C10: かぼちゃ | D10: 211.99097 | E10: 493.00226 | F10: 281.01129 | G10: 0.57 | H10: 227 | I10: 933.88093 | J10: 1 | K10: f | R10: s | S10: o | T10: o | U10: o | V10: f | W10: 25 | X10: 63.166667 | Y10: 12.5 | Z10: 246.50113 | AA10: 281.01129
A11: 51h | B11: 51 | C11: かぼちゃ | D11: 247.3228 | E11: 575.1693 | F11: 327.8465 | G11: 0.57 | H11: 135.8 | I11: 1821.2283 | J11: 1 | O11: s | P11: s | Q11: o | R11: o | S11: f | W11: 16.3 | X11: 34.1 | Y11: 35 | Z11: 575.1693 | AA11: 163.92325
A12: 52a | B12: 52 | C12: とうがん | D12: 1143 | E12: 3822.7425 | F12: 2679.7425 | G12: 0.701 | H12: 1094 | I12: 1044.7898 | J12: 3 | K12: f | L12: f | S12: s | T12: s | U12: o | V12: o | W12: 82.05 | X12: 109.4 | Y12: 355.55 | Z12: 1911.3712 | AA12: 1339.8712
A13: 52b | B13: 52 | C13: とうがん | D13: 1143 | E13: 3822.7425 | F13: 2679.7425 | G13: 0.701 | H13: 1094 | I13: 1044.7898 | J13: 3 | K13: o | L13: f | M13: f | T13: s | U13: s | V13: o | W13: 82.05 | X13: 109.4 | Y13: 355.55 | Z13: 1911.3712 | AA13: 1339.8712
A14: 52c | B14: 52 | C14: とうがん | D14: 1143 | E14: 3822.7425 | F14: 2679.7425 | G14: 0.701 | H14: 1094 | I14: 1044.7898 | J14: 3 | K14: s | L14: o | M14: o | N14: f | O14: f | V14: s | W14: 82.05 | X14: 109.4 | Y14: 355.55 | Z14: 1911.3712 | AA14: 1339.8712
A15: 52d | B15: 52 | C15: とうがん | D15: 1143 | E15: 3822.7425 | F15: 2679.7425 | G15: 0.701 | H15: 1094 | I15: 1044.7898 | J15: 3 | K15: s | L15: s | M15: o | N15: o | O15: f | P15: f | W15: 82.05 | X15: 109.4 | Y15: 355.55 | Z15: 1911.3712 | AA15: 1339.8712
A16: 53a | B16: 53 | C16: スイートコーン | D16: 87 | E16: 383.25991 | F16: 296.25991 | G16: 0.773 | H16: 230 | I16: 378.26087 | J16: 1 | K16: f | L16: f | S16: s | T16: o | U16: o | V16: o | W16: 34.5 | X16: 15.333333 | Y16: 74.75 | Z16: 191.62996 | AA16: 296.25991
A17: 53b | B17: 53 | C17: スイートコーン | D17: 87 | E17: 383.25991 | F17: 296.25991 | G17: 0.773 | H17: 230 | I17: 378.26087 | J17: 1 | K17: o | L17: f | M17: f | U17: s | V17: o | W17: 34.5 | X17: 23 | Y17: 74.75 | Z17: 191.62996 | AA17: 296.25991
A18: 54a | B18: 54 | C18: オクラ | D18: 389 | E18: 1691.3043 | F18: 1302.3043 | G18: 0.77 | H18: 1044 | I18: 372.60536 | J18: 1 | K18: f | L18: f | M18: f | T18: s | U18: o | V18: o | W18: 156.6 | X18: 104.4 | Y18: 226.2 | Z18: 563.76812 | AA18: 1302.3043
A19: 54b | B19: 54 | C19: オクラ | D19: 389 | E19: 1691.3043 | F19: 1302.3043 | G19: 0.77 | H19: 1044 | I19: 372.60536 | J19: 1 | K19: s | L19: o | M19: f | N19: f | O19: f | P19: f | W19: 156.6 | X19: 208.8 | Y19: 169.65 | Z19: 422.82609 | AA19: 1302.3043
A20: 54c | B20: 54 | C20: オクラ | D20: 389 | E20: 1691.3043 | F20: 1302.3043 | G20: 0.77 | H20: 1044 | I20: 372.60536 | J20: 1 | O20: s | P20: o | Q20: f | R20: f | S20: f | W20: 156.6 | X20: 208.8 | Y20: 226.2 | Z20: 563.76812 | AA20: 1302.3043
A21: 54d | B21: 54 | C21: オクラ | D21: 497.43583 | E21: 2162.7645 | F21: 1665.3287 | G21: 0.77 | H21: 1338.2 | I21: 371.7201 | J21: 1 | K21: s | L21: f | M21: f | N21: f | O21: f | P21: f | Q21: f | R21: f | U21: s | V21: s | W21: 19.5 | X21: 0 | Y21: 178 | Z21: 308.96636 | AA21: 555.10956
A22: 54e | B22: 54 | C22: オクラ | D22: 166.26516 | E22: 722.892 | F22: 556.62684 | G22: 0.77 | H22: 276 | I22: 602.41 | J22: 1 | K22: f | L22: f | M22: f | N22: f | U22: s | V22: o | W22: 31 | X22: 10 | Y22: 58 | Z22: 180.723 | AA22: 556.62684
A23: 54f | B23: 54 | C23: オクラ | D23: 389.317 | E23: 1689 | F23: 1299.683 | G23: 0.76949852 | H23: 1002 | I23: 388.53992 | J23: 1 | K23: o | L23: f | M23: f | N23: f | O23: f | P23: f | Q23: f | R23: f | U23: s | V23: s | W23: 48.5 | X23: 12.2 | Y23: 127.67143 | Z23: 241.28571 | AA23: 649.8415
A24: 54g | B24: 54 | C24: オクラ | D24: 150.316 | E24: 1520.1 | F24: 1369.784 | G24: 0.9011144 | H24: 1215.2 | I24: 123.69651 | J24: 1 | K24: f | L24: f | M24: f | N24: f | O24: f | P24: f | Q24: f | R24: f | T24: s | U24: o | V24: o | W24: 53 | X24: 23.4 | Y24: 142.35 | Z24: 190.0125 | AA24: 1369.784
A25: 55a | B25: 55 | C25: モロヘイヤ | D25: 1205 | E25: 2776.4977 | F25: 1571.4977 | G25: 0.566 | H25: 1090 | I25: 1105.5046 | J25: 0 | K25: s | L25: s | M25: f | N25: f | O25: f | P25: f | W25: 81.75 | X25: 218 | Y25: 231.625 | Z25: 694.12442 | AA25: 785.74885
A26: 55b | B26: 55 | C26: モロヘイヤ | D26: 1205 | E26: 2776.4977 | F26: 1571.4977 | G26: 0.566 | H26: 1090 | I26: 1105.5046 | J26: 0 | L26: s | M26: s | N26: f | O26: f | P26: f | Q26: f | W26: 81.75 | X26: 218 | Y26: 231.625 | Z26: 694.12442 | AA26: 785.74885
A27: 56a | B27: 56 | C27: キャベツ | D27: 208 | E27: 394.68691 | F27: 186.68691 | G27: 0.473 | H27: 129 | I27: 1612.4031 | J27: 1 | K27: s | L27: o | M27: o | N27: f | V27: s | W27: 9.675 | X27: 12.9 | Y27: 83.85 | Z27: 394.68691 | AA27: 93.343454
A28: 56b | B28: 56 | C28: キャベツ | D28: 208 | E28: 394.68691 | F28: 186.68691 | G28: 0.473 | H28: 129 | I28: 1612.4031 | J28: 1 | L28: s | M28: s | N28: o | O28: f | W28: 9.675 | X28: 25.8 | Y28: 83.85 | Z28: 394.68691 | AA28: 93.343454
A29: 56c | B29: 56 | C29: キャベツ | D29: 208 | E29: 394.68691 | F29: 186.68691 | G29: 0.473 | H29: 129 | I29: 1612.4031 | J29: 1 | M29: s | N29: o | O29: o | P29: f | W29: 19.35 | X29: 12.9 | Y29: 83.85 | Z29: 394.68691 | AA29: 186.68691
A30: 56d | B30: 56 | C30: キャベツ | D30: 208 | E30: 394.68691 | F30: 186.68691 | G30: 0.473 | H30: 129 | I30: 1612.4031 | J30: 1 | O30: s | P30: o | Q30: o | R30: f | W30: 19.35 | X30: 12.9 | Y30: 83.85 | Z30: 394.68691 | AA30: 186.68691
A31: 56e | B31: 56 | C31: キャベツ | D31: 208 | E31: 394.68691 | F31: 186.68691 | G31: 0.473 | H31: 129 | I31: 1612.4031 | J31: 1 | P31: s | Q31: s | R31: o | S31: f | W31: 9.675 | X31: 25.8 | Y31: 83.85 | Z31: 394.68691 | AA31: 93.343454
A32: 56f | B32: 56 | C32: キャベツ | D32: 208 | E32: 394.68691 | F32: 186.68691 | G32: 0.473 | H32: 129 | I32: 1612.4031 | J32: 1 | R32: s | S32: s | T32: o | U32: o | V32: f | W32: 9.675 | X32: 12.9 | Y32: 83.85 | Z32: 394.68691 | AA32: 93.343454
A33: 56g | B33: 56 | C33: キャベツ | D33: 208 | E33: 394.68691 | F33: 186.68691 | G33: 0.473 | H33: 129 | I33: 1612.4031 | J33: 1 | K33: o | L33: o | M33: f | U33: s | V33: s | W33: 9.675 | X33: 12.9 | Y33: 83.85 | Z33: 394.68691 | AA33: 93.343454
A34: 57a | B34: 57 | C34: レタス | D34: 407 | E34: 1100 | F34: 693 | G34: 0.63 | H34: 377 | I34: 1079.5756 | J34: 1 | K34: f | S34: s | T34: s | U34: o | V34: f | W34: 28.275 | X34: 75.4 | Y34: 122.525 | Z34: 550 | AA34: 346.5
A35: 57b | B35: 57 | C35: レタス | D35: 407 | E35: 1100 | F35: 693 | G35: 0.63 | H35: 377 | I35: 1079.5756 | J35: 1 | K35: f | L35: f | T35: s | U35: s | V35: o | W35: 28.275 | X35: 75.4 | Y35: 122.525 | Z35: 550 | AA35: 346.5
A36: 57c | B36: 57 | C36: レタス | D36: 407 | E36: 1100 | F36: 693 | G36: 0.63 | H36: 377 | I36: 1079.5756 | J36: 1 | O36: s | P36: o | Q36: f | R36: f | W36: 56.55 | X36: 75.4 | Y36: 122.525 | Z36: 550 | AA36: 693
A37: 57d | B37: 57 | C37: レタス | D37: 407 | E37: 1100 | F37: 693 | G37: 0.63 | H37: 377 | I37: 1079.5756 | J37: 1 | Q37: s | R37: o | S37: f | T37: f | W37: 56.55 | X37: 75.4 | Y37: 122.525 | Z37: 550 | AA37: 693
A38: 57e | B38: 57 | C38: レタス | D38: 407 | E38: 1100 | F38: 693 | G38: 0.63 | H38: 377 | I38: 1079.5756 | J38: 1 | R38: s | S38: o | T38: o | U38: f | V38: f | W38: 56.55 | X38: 37.7 | Y38: 122.525 | Z38: 550 | AA38: 693
A39: 58a | B39: 58 | C39: ばれいしょ | D39: 12 | E39: 300 | F39: 288 | G39: 0.96 | H39: 72 | I39: 166.66667 | J39: 3 | P39: s | Q39: o | R39: o | S39: o | T39: f | W39: 10.8 | X39: 4.8 | Y39: 46.8 | Z39: 300 | AA39: 288
A40: 58b | B40: 58 | C40: ばれいしょ | D40: 12 | E40: 300 | F40: 288 | G40: 0.96 | H40: 72 | I40: 166.66667 | J40: 3 | R40: s | S40: o | T40: o | U40: o | V40: f | W40: 10.8 | X40: 4.8 | Y40: 46.8 | Z40: 300 | AA40: 288
...

Sheet 固定資産
A1: 参照用固定
A2: キー | B2: 値 | C2: 単位
A3: asset_purchase | B3: 9673 | C3: 千円
A4: annual_depreciation | B4: 1347.9087 | C4: 千円/年
A5: plot_count | B5: 4 | C5: 区画
A6: annual_rent_thousand_yen | B6: 66.55 | C6: 千円/年
A7: land_purchase_thousand_yen | B7: 5908 | C7: 千円

Sheet 経営計画
A1: ＜輪作計画表＞
C2: 4 | D2: 5 | E2: 6 | F2: 7 | G2: 8 | H2: 9 | I2: 10 | J2: 11 | K2: 12 | L2: 1 | M2: 2 | N2: 3 | O2: 4 | P2: 5 | Q2: 6 | R2: 7 | S2: 8 | T2: 9 | U2: 10 | V2: 11 | W2: 12 | X2: 1 | Y2: 2 | Z2: 3 | AA2: 4 | AB2: 5 | AC2: 6 | AD2: 7 | AE2: 8 | AF2: 9 | AG2: 10 | AH2: 11 | AI2: 12 | AJ2: 1 | AK2: 2 | AL2: 3 | AM2: 4 | AN2: 5 | AO2: 6 | AP2: 7 | AQ2: 8 | AR2: 9 | AS2: 10 | AT2: 11 | AU2: 12 | AV2: 1 | AW2: 2 | AX2: 3 | AY2: 4
B3: A | E3: 56c | F3: 56c | G3: 56c | H3: 56c | K3: 59d | L3: 59d | M3: 59d | N3: 59d | S3: 57c | T3: 57c | U3: 57c | V3: 57c | Y3: 54e | Z3: 54e | AA3: 54e | AB3: 54e | AC3: 54e | AD3: 54e | AH3: 57e | AI3: 57e | AJ3: 57e | AK3: 57e | AL3: 57e | AO3: 56c | AP3: 56c | AQ3: 56c | AR3: 56c | AU3: 59d | AV3: 59d | AW3: 59d | AX3: 59d | AZ3: 20
B4: B | G4: 57c | H4: 57c | I4: 57c | J4: 57c | M4: 59a | N4: 59a | O4: 59a | P4: 59a | S4: 51h | T4: 51h | U4: 51h | V4: 51h | W4: 51h | Z4: 50a | AA4: 50a | AB4: 50a | AC4: 50a | AD4: 50a | AE4: 50a | AF4: 50a | AJ4: 57b | AK4: 57b | AL4: 57b | AM4: 57b | AN4: 57b | AQ4: 51h | AR4: 51h | AS4: 51h | AT4: 51h | AU4: 51h
B5: C | I5: 57d | J5: 57d | K5: 57d | L5: 57d | Q5: 56c | R5: 56c | S5: 56c | T5: 56c | W5: 59d | X5: 59d | Y5: 59d | Z5: 59d | AE5: 51h | AF5: 51h | AG5: 51h | AH5: 51h | AI5: 51h | AN5: 56b | AO5: 56b | AP5: 56b | AQ5: 56b | AT5: 57e | AU5: 57e | AV5: 57e | AW5: 57e | AX5: 57e
B6: D | D6: 56b | E6: 56b | F6: 56b | G6: 56b | L6: 57b | M6: 57b | N6: 57b | O6: 57b | P6: 57b | S6: 51h | T6: 51h | U6: 51h | V6: 51h | W6: 51h | Z6: 59b | AA6: 59b | AB6: 59b | AC6: 59b | AG6: 57d | AH6: 57d | AI6: 57d | AJ6: 57d | AQ6: 51h | AR6: 51h | AS6: 51h | AT6: 51h | AU6: 51h
B7: A | C7: =IF(C11="","",VLOOKUP(C3,栽培スケジュール!$A:$AN,MATCH("野菜名",栽培スケジュール!$1:$1,0),0)) | D7: =IF(D11="","",VLOOKUP(D3,栽培スケジュール!$A:$AN,MATCH("野菜名",栽培スケジュール!$1:$1,0),0)) | E7: =IF(E11="","",VLOOKUP(E3,栽培スケジュール!$A:$AN,MATCH("野菜名",栽培スケジュール!$1:$1,0),0)) -> キャベツ | F7: =IF(F11="","",VLOOKUP(F3,栽培スケジュール!$A:$AN,MATCH("野菜名",栽培スケジュール!$1:$1,0),0)) -> キャベツ | G7: =IF(G11="","",VLOOKUP(G3,栽培スケジュール!$A:$AN,MATCH("野菜名",栽培スケジュール!$1:$1,0),0)) -> キャベツ | H7: =IF(H11="","",VLOOKUP(H3,栽培スケジュール!$A:$AN,MATCH("野菜名",栽培スケジュール!$1:$1,0),0)) -> キャベツ | I7: =IF(I11="","",VLOOKUP(I3,栽培スケジュール!$A:$AN,MATCH("野菜名",栽培スケジュール!$1:$1,0),0)) | J7: =IF(J11="","",VLOOKUP(J3,栽培スケジュール!$A:$AN,MATCH("野菜名",栽培スケジュール!$1:$1,0),0)) | ... AY7: =IF(AY11="","",VLOOKUP(AY3,栽培スケジュール!$A:$AN,MATCH("野菜名",栽培スケジュール!$1:$1,0),0))
B8: B | C8: =IF(C12="","",VLOOKUP(C4,栽培スケジュール!$A:$AN,MATCH("野菜名",栽培スケジュール!$1:$1,0),0)) | D8: =IF(D12="","",VLOOKUP(D4,栽培スケジュール!$A:$AN,MATCH("野菜名",栽培スケジュール!$1:$1,0),0)) | E8: =IF(E12="","",VLOOKUP(E4,栽培スケジュール!$A:$AN,MATCH("野菜名",栽培スケジュール!$1:$1,0),0)) | F8: =IF(F12="","",VLOOKUP(F4,栽培スケジュール!$A:$AN,MATCH("野菜名",栽培スケジュール!$1:$1,0),0)) | G8: =IF(G12="","",VLOOKUP(G4,栽培スケジュール!$A:$AN,MATCH("野菜名",栽培スケジュール!$1:$1,0),0)) -> レタス | H8: =IF(H12="","",VLOOKUP(H4,栽培スケジュール!$A:$AN,MATCH("野菜名",栽培スケジュール!$1:$1,0),0)) -> レタス | I8: =IF(I12="","",VLOOKUP(I4,栽培スケジュール!$A:$AN,MATCH("野菜名",栽培スケジュール!$1:$1,0),0)) -> レタス | J8: =IF(J12="","",VLOOKUP(J4,栽培スケジュール!$A:$AN,MATCH("野菜名",栽培スケジュール!$1:$1,0),0)) -> レタス | ... AY8: =IF(AY12="","",VLOOKUP(AY4,栽培スケジュール!$A:$AN,MATCH("野菜名",栽培スケジュール!$1:$1,0),0))
B9: C | C9: =IF(C13="","",VLOOKUP(C5,栽培スケジュール!$A:$AN,MATCH("野菜名",栽培スケジュール!$1:$1,0),0)) | D9: =IF(D13="","",VLOOKUP(D5,栽培スケジュール!$A:$AN,MATCH("野菜名",栽培スケジュール!$1:$1,0),0)) | E9: =IF(E13="","",VLOOKUP(E5,栽培スケジュール!$A:$AN,MATCH("野菜名",栽培スケジュール!$1:$1,0),0)) | F9: =IF(F13="","",VLOOKUP(F5,栽培スケジュール!$A:$AN,MATCH("野菜名",栽培スケジュール!$1:$1,0),0)) | G9: =IF(G13="","",VLOOKUP(G5,栽培スケジュール!$A:$AN,MATCH("野菜名",栽培スケジュール!$1:$1,0),0)) | H9: =IF(H13="","",VLOOKUP(H5,栽培スケジュール!$A:$AN,MATCH("野菜名",栽培スケジュール!$1:$1,0),0)) | I9: =IF(I13="","",VLOOKUP(I5,栽培スケジュール!$A:$AN,MATCH("野菜名",栽培スケジュール!$1:$1,0),0)) -> レタス | J9: =IF(J13="","",VLOOKUP(J5,栽培スケジュール!$A:$AN,MATCH("野菜名",栽培スケジュール!$1:$1,0),0)) -> レタス | ... AY9: =IF(AY13="","",VLOOKUP(AY5,栽培スケジュール!$A:$AN,MATCH("野菜名",栽培スケジュール!$1:$1,0),0))
B10: D | C10: =IF(C14="","",VLOOKUP(C6,栽培スケジュール!$A:$AN,MATCH("野菜名",栽培スケジュール!$1:$1,0),0)) | D10: =IF(D14="","",VLOOKUP(D6,栽培スケジュール!$A:$AN,MATCH("野菜名",栽培スケジュール!$1:$1,0),0)) -> キャベツ | E10: =IF(E14="","",VLOOKUP(E6,栽培スケジュール!$A:$AN,MATCH("野菜名",栽培スケジュール!$1:$1,0),0)) -> キャベツ | F10: =IF(F14="","",VLOOKUP(F6,栽培スケジュール!$A:$AN,MATCH("野菜名",栽培スケジュール!$1:$1,0),0)) -> キャベツ | G10: =IF(G14="","",VLOOKUP(G6,栽培スケジュール!$A:$AN,MATCH("野菜名",栽培スケジュール!$1:$1,0),0)) -> キャベツ | H10: =IF(H14="","",VLOOKUP(H6,栽培スケジュール!$A:$AN,MATCH("野菜名",栽培スケジュール!$1:$1,0),0)) | I10: =IF(I14="","",VLOOKUP(I6,栽培スケジュール!$A:$AN,MATCH("野菜名",栽培スケジュール!$1:$1,0),0)) | J10: =IF(J14="","",VLOOKUP(J6,栽培スケジュール!$A:$AN,MATCH("野菜名",栽培スケジュール!$1:$1,0),0)) | ... AY10: =IF(AY14="","",VLOOKUP(AY6,栽培スケジュール!$A:$AN,MATCH("野菜名",栽培スケジュール!$1:$1,0),0))
B11: A | E11: s | F11: o | G11: o | H11: f | K11: s | L11: o | M11: f | N11: f | S11: s | T11: o | U11: f | V11: f | Y11: s | Z11: o | AA11: f | AB11: f | AC11: f | AD11: f | AH11: s | AI11: o | AJ11: o | AK11: f | AL11: f | AO11: s | AP11: o | AQ11: o | AR11: f | AU11: s | AV11: o | AW11: f | AX11: f
B12: B | G12: s | H12: o | I12: f | J12: f | M12: s | N12: o | O12: f | P12: f | S12: s | T12: s | U12: o | V12: o | W12: f | Z12: s | AA12: s | AB12: o | AC12: o | AD12: f | AE12: f | AF12: f | AJ12: s | AK12: s | AL12: o | AM12: f | AN12: f | AQ12: s | AR12: s | AS12: o | AT12: o | AU12: f
B13: C | I13: s | J13: o | K13: f | L13: f | Q13: s | R13: o | S13: o | T13: f | W13: s | X13: o | Y13: f | Z13: f | AE13: s | AF13: s | AG13: o | AH13: o | AI13: f | AN13: s | AO13: s | AP13: o | AQ13: f | AT13: s | AU13: o | AV13: o | AW13: f | AX13: f
B14: D | D14: s | E14: s | F14: o | G14: f | L14: s | M14: s | N14: o | O14: f | P14: f | S14: s | T14: s | U14: o | V14: o | W14: f | Z14: s | AA14: o | AB14: f | AC14: f | AG14: s | AH14: o | AI14: f | AJ14: f | AQ14: s | AR14: s | AS14: o | AT14: o | AU14: f
A16: ＜労働時間算定表＞ | AX16: 単位：時間
C17: 4 | D17: 5 | E17: 6 | F17: 7 | G17: 8 | H17: 9 | I17: 10 | J17: 11 | K17: 12 | L17: 1 | M17: 2 | N17: 3 | O17: 4 | P17: 5 | Q17: 6 | R17: 7 | S17: 8 | T17: 9 | U17: 10 | V17: 11 | W17: 12 | X17: 1 | Y17: 2 | Z17: 3 | AA17: 4 | AB17: 5 | AC17: 6 | AD17: 7 | AE17: 8 | AF17: 9 | AG17: 10 | AH17: 11 | AI17: 12 | AJ17: 1 | AK17: 2 | AL17: 3 | AM17: 4 | AN17: 5 | AO17: 6 | AP17: 7 | AQ17: 8 | AR17: 9 | AS17: 10 | AT17: 11 | AU17: 12 | AV17: 1 | AW17: 2 | AX17: 3 | AY17: 4
B18: A | C18: =IF(C11="","",VLOOKUP(C3,栽培スケジュール!$A:$AN,IF(ISNUMBER(SEARCH("s",C11)),MATCH("s(h)",栽培スケジュール!$1:$1,0),IF(ISNUMBER(SEARCH("o",C11)),MATCH("o(h)",栽培スケジュール!$1:$1,0),MATCH("f(h)",栽培スケジュール!$1:$1,0))),0)) | D18: =IF(D11="","",VLOOKUP(D3,栽培スケジュール!$A:$AN,IF(ISNUMBER(SEARCH("s",D11)),MATCH("s(h)",栽培スケジュール!$1:$1,0),IF(ISNUMBER(SEARCH("o",D11)),MATCH("o(h)",栽培スケジュール!$1:$1,0),MATCH("f(h)",栽培スケジュール!$1:$1,0))),0)) | E18: =IF(E11="","",VLOOKUP(E3,栽培スケジュール!$A:$AN,IF(ISNUMBER(SEARCH("s",E11)),MATCH("s(h)",栽培スケジュール!$1:$1,0),IF(ISNUMBER(SEARCH("o",E11)),MATCH("o(h)",栽培スケジュール!$1:$1,0),MATCH("f(h)",栽培スケジュール!$1:$1,0))),0)) -> 19.35 | F18: =IF(F11="","",VLOOKUP(F3,栽培スケジュール!$A:$AN,IF(ISNUMBER(SEARCH("s",F11)),MATCH("s(h)",栽培スケジュール!$1:$1,0),IF(ISNUMBER(SEARCH("o",F11)),MATCH("o(h)",栽培スケジュール!$1:$1,0),MATCH("f(h)",栽培スケジュール!$1:$1,0))),0)) -> 12.9 | G18: =IF(G11="","",VLOOKUP(G3,栽培スケジュール!$A:$AN,IF(ISNUMBER(SEARCH("s",G11)),MATCH("s(h)",栽培スケジュール!$1:$1,0),IF(ISNUMBER(SEARCH("o",G11)),MATCH("o(h)",栽培スケジュール!$1:$1,0),MATCH("f(h)",栽培スケジュール!$1:$1,0))),0)) -> 12.9 | H18: =IF(H11="","",VLOOKUP(H3,栽培スケジュール!$A:$AN,IF(ISNUMBER(SEARCH("s",H11)),MATCH("s(h)",栽培スケジュール!$1:$1,0),IF(ISNUMBER(SEARCH("o",H11)),MATCH("o(h)",栽培スケジュール!$1:$1,0),MATCH("f(h)",栽培スケジュール!$1:$1,0))),0)) -> 83.85 | I18: =IF(I11="","",VLOOKUP(I3,栽培スケジュール!$A:$AN,IF(ISNUMBER(SEARCH("s",I11)),MATCH("s(h)",栽培スケジュール!$1:$1,0),IF(ISNUMBER(SEARCH("o",I11)),MATCH("o(h)",栽培スケジュール!$1:$1,0),MATCH("f(h)",栽培スケジュール!$1:$1,0))),0)) | J18: =IF(J11="","",VLOOKUP(J3,栽培スケジュール!$A:$AN,IF(ISNUMBER(SEARCH("s",J11)),MATCH("s(h)",栽培スケジュール!$1:$1,0),IF(ISNUMBER(SEARCH("o",J11)),MATCH("o(h)",栽培スケジュール!$1:$1,0),MATCH("f(h)",栽培スケジュール!$1:$1,0))),0)) | ... AY18: =IF(AY11="","",VLOOKUP(AY3,栽培スケジュール!$A:$AN,IF(ISNUMBER(SEARCH("s",AY11)),MATCH("s(h)",栽培スケジュール!$1:$1,0),IF(ISNUMBER(SEARCH("o",AY11)),MATCH("o(h)",栽培スケジュール!$1:$1,0),MATCH("f(h)",栽培スケジュール!$1:$1,0))),0))
B19: B | C19: =IF(C12="","",VLOOKUP(C4,栽培スケジュール!$A:$AN,IF(ISNUMBER(SEARCH("s",C12)),MATCH("s(h)",栽培スケジュール!$1:$1,0),IF(ISNUMBER(SEARCH("o",C12)),MATCH("o(h)",栽培スケジュール!$1:$1,0),MATCH("f(h)",栽培スケジュール!$1:$1,0))),0)) | D19: =IF(D12="","",VLOOKUP(D4,栽培スケジュール!$A:$AN,IF(ISNUMBER(SEARCH("s",D12)),MATCH("s(h)",栽培スケジュール!$1:$1,0),IF(ISNUMBER(SEARCH("o",D12)),MATCH("o(h)",栽培スケジュール!$1:$1,0),MATCH("f(h)",栽培スケジュール!$1:$1,0))),0)) | E19: =IF(E12="","",VLOOKUP(E4,栽培スケジュール!$A:$AN,IF(ISNUMBER(SEARCH("s",E12)),MATCH("s(h)",栽培スケジュール!$1:$1,0),IF(ISNUMBER(SEARCH("o",E12)),MATCH("o(h)",栽培スケジュール!$1:$1,0),MATCH("f(h)",栽培スケジュール!$1:$1,0))),0)) | F19: =IF(F12="","",VLOOKUP(F4,栽培スケジュール!$A:$AN,IF(ISNUMBER(SEARCH("s",F12)),MATCH("s(h)",栽培スケジュール!$1:$1,0),IF(ISNUMBER(SEARCH("o",F12)),MATCH("o(h)",栽培スケジュール!$1:$1,0),MATCH("f(h)",栽培スケジュール!$1:$1,0))),0)) | G19: =IF(G12="","",VLOOKUP(G4,栽培スケジュール!$A:$AN,IF(ISNUMBER(SEARCH("s",G12)),MATCH("s(h)",栽培スケジュール!$1:$1,0),IF(ISNUMBER(SEARCH("o",G12)),MATCH("o(h)",栽培スケジュール!$1:$1,0),MATCH("f(h)",栽培スケジュール!$1:$1,0))),0)) -> 56.55 | H19: =IF(H12="","",VLOOKUP(H4,栽培スケジュール!$A:$AN,IF(ISNUMBER(SEARCH("s",H12)),MATCH("s(h)",栽培スケジュール!$1:$1,0),IF(ISNUMBER(SEARCH("o",H12)),MATCH("o(h)",栽培スケジュール!$1:$1,0),MATCH("f(h)",栽培スケジュール!$1:$1,0))),0)) -> 75.4 | I19: =IF(I12="","",VLOOKUP(I4,栽培スケジュール!$A:$AN,IF(ISNUMBER(SEARCH("s",I12)),MATCH("s(h)",栽培スケジュール!$1:$1,0),IF(ISNUMBER(SEARCH("o",I12)),MATCH("o(h)",栽培スケジュール!$1:$1,0),MATCH("f(h)",栽培スケジュール!$1:$1,0))),0)) -> 122.525 | J19: =IF(J12="","",VLOOKUP(J4,栽培スケジュール!$A:$AN,IF(ISNUMBER(SEARCH("s",J12)),MATCH("s(h)",栽培スケジュール!$1:$1,0),IF(ISNUMBER(SEARCH("o",J12)),MATCH("o(h)",栽培スケジュール!$1:$1,0),MATCH("f(h)",栽培スケジュール!$1:$1,0))),0)) -> 122.525 | ... AY19: =IF(AY12="","",VLOOKUP(AY4,栽培スケジュール!$A:$AN,IF(ISNUMBER(SEARCH("s",AY12)),MATCH("s(h)",栽培スケジュール!$1:$1,0),IF(ISNUMBER(SEARCH("o",AY12)),MATCH("o(h)",栽培スケジュール!$1:$1,0),MATCH("f(h)",栽培スケジュール!$1:$1,0))),0))
B20: C | C20: =IF(C13="","",VLOOKUP(C5,栽培スケジュール!$A:$AN,IF(ISNUMBER(SEARCH("s",C13)),MATCH("s(h)",栽培スケジュール!$1:$1,0),IF(ISNUMBER(SEARCH("o",C13)),MATCH("o(h)",栽培スケジュール!$1:$1,0),MATCH("f(h)",栽培スケジュール!$1:$1,0))),0)) | D20: =IF(D13="","",VLOOKUP(D5,栽培スケジュール!$A:$AN,IF(ISNUMBER(SEARCH("s",D13)),MATCH("s(h)",栽培スケジュール!$1:$1,0),IF(ISNUMBER(SEARCH("o",D13)),MATCH("o(h)",栽培スケジュール!$1:$1,0),MATCH("f(h)",栽培スケジュール!$1:$1,0))),0)) | E20: =IF(E13="","",VLOOKUP(E5,栽培スケジュール!$A:$AN,IF(ISNUMBER(SEARCH("s",E13)),MATCH("s(h)",栽培スケジュール!$1:$1,0),IF(ISNUMBER(SEARCH("o",E13)),MATCH("o(h)",栽培スケジュール!$1:$1,0),MATCH("f(h)",栽培スケジュール!$1:$1,0))),0)) | F20: =IF(F13="","",VLOOKUP(F5,栽培スケジュール!$A:$AN,IF(ISNUMBER(SEARCH("s",F13)),MATCH("s(h)",栽培スケジュール!$1:$1,0),IF(ISNUMBER(SEARCH("o",F13)),MATCH("o(h)",栽培スケジュール!$1:$1,0),MATCH("f(h)",栽培スケジュール!$1:$1,0))),0)) | G20: =IF(G13="","",VLOOKUP(G5,栽培スケジュール!$A:$AN,IF(ISNUMBER(SEARCH("s",G13)),MATCH("s(h)",栽培スケジュール!$1:$1,0),IF(ISNUMBER(SEARCH("o",G13)),MATCH("o(h)",栽培スケジュール!$1:$1,0),MATCH("f(h)",栽培スケジュール!$1:$1,0))),0)) | H20: =IF(H13="","",VLOOKUP(H5,栽培スケジュール!$A:$AN,IF(ISNUMBER(SEARCH("s",H13)),MATCH("s(h)",栽培スケジュール!$1:$1,0),IF(ISNUMBER(SEARCH("o",H13)),MATCH("o(h)",栽培スケジュール!$1:$1,0),MATCH("f(h)",栽培スケジュール!$1:$1,0))),0)) | I20: =IF(I13="","",VLOOKUP(I5,栽培スケジュール!$A:$AN,IF(ISNUMBER(SEARCH("s",I13)),MATCH("s(h)",栽培スケジュール!$1:$1,0),IF(ISNUMBER(SEARCH("o",I13)),MATCH("o(h)",栽培スケジュール!$1:$1,0),MATCH("f(h)",栽培スケジュール!$1:$1,0))),0)) -> 56.55 | J20: =IF(J13="","",VLOOKUP(J5,栽培スケジュール!$A:$AN,IF(ISNUMBER(SEARCH("s",J13)),MATCH("s(h)",栽培スケジュール!$1:$1,0),IF(ISNUMBER(SEARCH("o",J13)),MATCH("o(h)",栽培スケジュール!$1:$1,0),MATCH("f(h)",栽培スケジュール!$1:$1,0))),0)) -> 75.4 | ... AY20: =IF(AY13="","",VLOOKUP(AY5,栽培スケジュール!$A:$AN,IF(ISNUMBER(SEARCH("s",AY13)),MATCH("s(h)",栽培スケジュール!$1:$1,0),IF(ISNUMBER(SEARCH("o",AY13)),MATCH("o(h)",栽培スケジュール!$1:$1,0),MATCH("f(h)",栽培スケジュール!$1:$1,0))),0))
B21: D | C21: =IF(C14="","",VLOOKUP(C6,栽培スケジュール!$A:$AN,IF(ISNUMBER(SEARCH("s",C14)),MATCH("s(h)",栽培スケジュール!$1:$1,0),IF(ISNUMBER(SEARCH("o",C14)),MATCH("o(h)",栽培スケジュール!$1:$1,0),MATCH("f(h)",栽培スケジュール!$1:$1,0))),0)) | D21: =IF(D14="","",VLOOKUP(D6,栽培スケジュール!$A:$AN,IF(ISNUMBER(SEARCH("s",D14)),MATCH("s(h)",栽培スケジュール!$1:$1,0),IF(ISNUMBER(SEARCH("o",D14)),MATCH("o(h)",栽培スケジュール!$1:$1,0),MATCH("f(h)",栽培スケジュール!$1:$1,0))),0)) -> 9.675 | E21: =IF(E14="","",VLOOKUP(E6,栽培スケジュール!$A:$AN,IF(ISNUMBER(SEARCH("s",E14)),MATCH("s(h)",栽培スケジュール!$1:$1,0),IF(ISNUMBER(SEARCH("o",E14)),MATCH("o(h)",栽培スケジュール!$1:$1,0),MATCH("f(h)",栽培スケジュール!$1:$1,0))),0)) -> 9.675 | F21: =IF(F14="","",VLOOKUP(F6,栽培スケジュール!$A:$AN,IF(ISNUMBER(SEARCH("s",F14)),MATCH("s(h)",栽培スケジュール!$1:$1,0),IF(ISNUMBER(SEARCH("o",F14)),MATCH("o(h)",栽培スケジュール!$1:$1,0),MATCH("f(h)",栽培スケジュール!$1:$1,0))),0)) -> 25.8 | G21: =IF(G14="","",VLOOKUP(G6,栽培スケジュール!$A:$AN,IF(ISNUMBER(SEARCH("s",G14)),MATCH("s(h)",栽培スケジュール!$1:$1,0),IF(ISNUMBER(SEARCH("o",G14)),MATCH("o(h)",栽培スケジュール!$1:$1,0),MATCH("f(h)",栽培スケジュール!$1:$1,0))),0)) -> 83.85 | H21: =IF(H14="","",VLOOKUP(H6,栽培スケジュール!$A:$AN,IF(ISNUMBER(SEARCH("s",H14)),MATCH("s(h)",栽培スケジュール!$1:$1,0),IF(ISNUMBER(SEARCH("o",H14)),MATCH("o(h)",栽培スケジュール!$1:$1,0),MATCH("f(h)",栽培スケジュール!$1:$1,0))),0)) | I21: =IF(I14="","",VLOOKUP(I6,栽培スケジュール!$A:$AN,IF(ISNUMBER(SEARCH("s",I14)),MATCH("s(h)",栽培スケジュール!$1:$1,0),IF(ISNUMBER(SEARCH("o",I14)),MATCH("o(h)",栽培スケジュール!$1:$1,0),MATCH("f(h)",栽培スケジュール!$1:$1,0))),0)) | J21: =IF(J14="","",VLOOKUP(J6,栽培スケジュール!$A:$AN,IF(ISNUMBER(SEARCH("s",J14)),MATCH("s(h)",栽培スケジュール!$1:$1,0),IF(ISNUMBER(SEARCH("o",J14)),MATCH("o(h)",栽培スケジュール!$1:$1,0),MATCH("f(h)",栽培スケジュール!$1:$1,0))),0)) | ... AY21: =IF(AY14="","",VLOOKUP(AY6,栽培スケジュール!$A:$AN,IF(ISNUMBER(SEARCH("s",AY14)),MATCH("s(h)",栽培スケジュール!$1:$1,0),IF(ISNUMBER(SEARCH("o",AY14)),MATCH("o(h)",栽培スケジュール!$1:$1,0),MATCH("f(h)",栽培スケジュール!$1:$1,0))),0))
B22: 合計 | C22: =SUM(C18:C21) -> 0 | D22: =SUM(D18:D21) -> 9.675 | E22: =SUM(E18:E21) -> 29.025 | F22: =SUM(F18:F21) -> 38.7 | G22: =SUM(G18:G21) -> 153.3 | H22: =SUM(H18:H21) -> 159.25 | I22: =SUM(I18:I21) -> 179.075 | J22: =SUM(J18:J21) -> 197.925 | ... AY22: =SUM(AY18:AY21) -> 0
A24: <簡易月次PL> | AX24: 単位：千円
C25: 4 | D25: 5 | E25: 6 | F25: 7 | G25: 8 | H25: 9 | I25: 10 | J25: 11 | K25: 12 | L25: 1 | M25: 2 | N25: 3 | O25: 4 | P25: 5 | Q25: 6 | R25: 7 | S25: 8 | T25: 9 | U25: 10 | V25: 11 | W25: 12 | X25: 1 | Y25: 2 | Z25: 3 | AA25: 4 | AB25: 5 | AC25: 6 | AD25: 7 | AE25: 8 | AF25: 9 | AG25: 10 | AH25: 11 | AI25: 12 | AJ25: 1 | AK25: 2 | AL25: 3 | AM25: 4 | AN25: 5 | AO25: 6 | AP25: 7 | AQ25: 8 | AR25: 9 | AS25: 10 | AT25: 11 | AU25: 12 | AV25: 1 | AW25: 2 | AX25: 3 | AY25: 4
B26: 粗収益 | C26: =SUM(C27:C30) -> 0 | D26: =SUM(D27:D30) -> 0 | E26: =SUM(E27:E30) -> 0 | F26: =SUM(F27:F30) -> 0 | G26: =SUM(G27:G30) -> 394.68691 | H26: =SUM(H27:H30) -> 394.68691 | I26: =SUM(I27:I30) -> 550 | J26: =SUM(J27:J30) -> 550 | ... AY26: =SUM(AY27:AY30) -> 0
B27: A | C27: =IF(ISNUMBER(SEARCH("f",C11)),VLOOKUP(C3,栽培スケジュール!$A:$AN,MATCH("粗収益/月",栽培スケジュール!$1:$1,0),0),"") | D27: =IF(ISNUMBER(SEARCH("f",D11)),VLOOKUP(D3,栽培スケジュール!$A:$AN,MATCH("粗収益/月",栽培スケジュール!$1:$1,0),0),"") | E27: =IF(ISNUMBER(SEARCH("f",E11)),VLOOKUP(E3,栽培スケジュール!$A:$AN,MATCH("粗収益/月",栽培スケジュール!$1:$1,0),0),"") | F27: =IF(ISNUMBER(SEARCH("f",F11)),VLOOKUP(F3,栽培スケジュール!$A:$AN,MATCH("粗収益/月",栽培スケジュール!$1:$1,0),0),"") | G27: =IF(ISNUMBER(SEARCH("f",G11)),VLOOKUP(G3,栽培スケジュール!$A:$AN,MATCH("粗収益/月",栽培スケジュール!$1:$1,0),0),"") | H27: =IF(ISNUMBER(SEARCH("f",H11)),VLOOKUP(H3,栽培スケジュール!$A:$AN,MATCH("粗収益/月",栽培スケジュール!$1:$1,0),0),"") -> 394.68691 | I27: =IF(ISNUMBER(SEARCH("f",I11)),VLOOKUP(I3,栽培スケジュール!$A:$AN,MATCH("粗収益/月",栽培スケジュール!$1:$1,0),0),"") | J27: =IF(ISNUMBER(SEARCH("f",J11)),VLOOKUP(J3,栽培スケジュール!$A:$AN,MATCH("粗収益/月",栽培スケジュール!$1:$1,0),0),"") | ... AY27: =IF(ISNUMBER(SEARCH("f",AY11)),VLOOKUP(AY3,栽培スケジュール!$A:$AN,MATCH("粗収益/月",栽培スケジュール!$1:$1,0),0),"")
B28: B | C28: =IF(ISNUMBER(SEARCH("f",C12)),VLOOKUP(C4,栽培スケジュール!$A:$AN,MATCH("粗収益/月",栽培スケジュール!$1:$1,0),0),"") | D28: =IF(ISNUMBER(SEARCH("f",D12)),VLOOKUP(D4,栽培スケジュール!$A:$AN,MATCH("粗収益/月",栽培スケジュール!$1:$1,0),0),"") | E28: =IF(ISNUMBER(SEARCH("f",E12)),VLOOKUP(E4,栽培スケジュール!$A:$AN,MATCH("粗収益/月",栽培スケジュール!$1:$1,0),0),"") | F28: =IF(ISNUMBER(SEARCH("f",F12)),VLOOKUP(F4,栽培スケジュール!$A:$AN,MATCH("粗収益/月",栽培スケジュール!$1:$1,0),0),"") | G28: =IF(ISNUMBER(SEARCH("f",G12)),VLOOKUP(G4,栽培スケジュール!$A:$AN,MATCH("粗収益/月",栽培スケジュール!$1:$1,0),0),"") | H28: =IF(ISNUMBER(SEARCH("f",H12)),VLOOKUP(H4,栽培スケジュール!$A:$AN,MATCH("粗収益/月",栽培スケジュール!$1:$1,0),0),"") | I28: =IF(ISNUMBER(SEARCH("f",I12)),VLOOKUP(I4,栽培スケジュール!$A:$AN,MATCH("粗収益/月",栽培スケジュール!$1:$1,0),0),"") -> 550 | J28: =IF(ISNUMBER(SEARCH("f",J12)),VLOOKUP(J4,栽培スケジュール!$A:$AN,MATCH("粗収益/月",栽培スケジュール!$1:$1,0),0),"") -> 550 | ... AY28: =IF(ISNUMBER(SEARCH("f",AY12)),VLOOKUP(AY4,栽培スケジュール!$A:$AN,MATCH("粗収益/月",栽培スケジュール!$1:$1,0),0),"")
B29: C | C29: =IF(ISNUMBER(SEARCH("f",C13)),VLOOKUP(C5,栽培スケジュール!$A:$AN,MATCH("粗収益/月",栽培スケジュール!$1:$1,0),0),"") | D29: =IF(ISNUMBER(SEARCH("f",D13)),VLOOKUP(D5,栽培スケジュール!$A:$AN,MATCH("粗収益/月",栽培スケジュール!$1:$1,0),0),"") | E29: =IF(ISNUMBER(SEARCH("f",E13)),VLOOKUP(E5,栽培スケジュール!$A:$AN,MATCH("粗収益/月",栽培スケジュール!$1:$1,0),0),"") | F29: =IF(ISNUMBER(SEARCH("f",F13)),VLOOKUP(F5,栽培スケジュール!$A:$AN,MATCH("粗収益/月",栽培スケジュール!$1:$1,0),0),"") | G29: =IF(ISNUMBER(SEARCH("f",G13)),VLOOKUP(G5,栽培スケジュール!$A:$AN,MATCH("粗収益/月",栽培スケジュール!$1:$1,0),0),"") | H29: =IF(ISNUMBER(SEARCH("f",H13)),VLOOKUP(H5,栽培スケジュール!$A:$AN,MATCH("粗収益/月",栽培スケジュール!$1:$1,0),0),"") | I29: =IF(ISNUMBER(SEARCH("f",I13)),VLOOKUP(I5,栽培スケジュール!$A:$AN,MATCH("粗収益/月",栽培スケジュール!$1:$1,0),0),"") | J29: =IF(ISNUMBER(SEARCH("f",J13)),VLOOKUP(J5,栽培スケジュール!$A:$AN,MATCH("粗収益/月",栽培スケジュール!$1:$1,0),0),"") | ... AY29: =IF(ISNUMBER(SEARCH("f",AY13)),VLOOKUP(AY5,栽培スケジュール!$A:$AN,MATCH("粗収益/月",栽培スケジュール!$1:$1,0),0),"")
B30: D | C30: =IF(ISNUMBER(SEARCH("f",C14)),VLOOKUP(C6,栽培スケジュール!$A:$AN,MATCH("粗収益/月",栽培スケジュール!$1:$1,0),0),"") | D30: =IF(ISNUMBER(SEARCH("f",D14)),VLOOKUP(D6,栽培スケジュール!$A:$AN,MATCH("粗収益/月",栽培スケジュール!$1:$1,0),0),"") | E30: =IF(ISNUMBER(SEARCH("f",E14)),VLOOKUP(E6,栽培スケジュール!$A:$AN,MATCH("粗収益/月",栽培スケジュール!$1:$1,0),0),"") | F30: =IF(ISNUMBER(SEARCH("f",F14)),VLOOKUP(F6,栽培スケジュール!$A:$AN,MATCH("粗収益/月",栽培スケジュール!$1:$1,0),0),"") | G30: =IF(ISNUMBER(SEARCH("f",G14)),VLOOKUP(G6,栽培スケジュール!$A:$AN,MATCH("粗収益/月",栽培スケジュール!$1:$1,0),0),"") -> 394.68691 | H30: =IF(ISNUMBER(SEARCH("f",H14)),VLOOKUP(H6,栽培スケジュール!$A:$AN,MATCH("粗収益/月",栽培スケジュール!$1:$1,0),0),"") | I30: =IF(ISNUMBER(SEARCH("f",I14)),VLOOKUP(I6,栽培スケジュール!$A:$AN,MATCH("粗収益/月",栽培スケジュール!$1:$1,0),0),"") | J30: =IF(ISNUMBER(SEARCH("f",J14)),VLOOKUP(J6,栽培スケジュール!$A:$AN,MATCH("粗収益/月",栽培スケジュール!$1:$1,0),0),"") | ... AY30: =IF(ISNUMBER(SEARCH("f",AY14)),VLOOKUP(AY6,栽培スケジュール!$A:$AN,MATCH("粗収益/月",栽培スケジュール!$1:$1,0),0),"")
B31: 経営費 | C31: =SUM(C32:C35) -> 0 | D31: =SUM(D32:D35) -> 93.343454 | E31: =SUM(E32:E35) -> 280.03036 | F31: =SUM(F32:F35) -> 0 | G31: =SUM(G32:G35) -> 693 | H31: =SUM(H32:H35) -> 0 | I31: =SUM(I32:I35) -> 693 | J31: =SUM(J32:J35) -> 0 | ... AY31: =SUM(AY32:AY35) -> 0
B32: A | C32: =IF(ISNUMBER(SEARCH("s",C11)),VLOOKUP(C3,栽培スケジュール!$A:$AN,IFERROR(MATCH("経営費/月",栽培スケジュール!$1:$1,0),MATCH("経営費(減価償却費除く)",栽培スケジュール!$1:$1,0)),0),"") | D32: =IF(ISNUMBER(SEARCH("s",D11)),VLOOKUP(D3,栽培スケジュール!$A:$AN,IFERROR(MATCH("経営費/月",栽培スケジュール!$1:$1,0),MATCH("経営費(減価償却費除く)",栽培スケジュール!$1:$1,0)),0),"") | E32: =IF(ISNUMBER(SEARCH("s",E11)),VLOOKUP(E3,栽培スケジュール!$A:$AN,IFERROR(MATCH("経営費/月",栽培スケジュール!$1:$1,0),MATCH("経営費(減価償却費除く)",栽培スケジュール!$1:$1,0)),0),"") -> 186.68691 | F32: =IF(ISNUMBER(SEARCH("s",F11)),VLOOKUP(F3,栽培スケジュール!$A:$AN,IFERROR(MATCH("経営費/月",栽培スケジュール!$1:$1,0),MATCH("経営費(減価償却費除く)",栽培スケジュール!$1:$1,0)),0),"") | G32: =IF(ISNUMBER(SEARCH("s",G11)),VLOOKUP(G3,栽培スケジュール!$A:$AN,IFERROR(MATCH("経営費/月",栽培スケジュール!$1:$1,0),MATCH("経営費(減価償却費除く)",栽培スケジュール!$1:$1,0)),0),"") | H32: =IF(ISNUMBER(SEARCH("s",H11)),VLOOKUP(H3,栽培スケジュール!$A:$AN,IFERROR(MATCH("経営費/月",栽培スケジュール!$1:$1,0),MATCH("経営費(減価償却費除く)",栽培スケジュール!$1:$1,0)),0),"") | I32: =IF(ISNUMBER(SEARCH("s",I11)),VLOOKUP(I3,栽培スケジュール!$A:$AN,IFERROR(MATCH("経営費/月",栽培スケジュール!$1:$1,0),MATCH("経営費(減価償却費除く)",栽培スケジュール!$1:$1,0)),0),"") | J32: =IF(ISNUMBER(SEARCH("s",J11)),VLOOKUP(J3,栽培スケジュール!$A:$AN,IFERROR(MATCH("経営費/月",栽培スケジュール!$1:$1,0),MATCH("経営費(減価償却費除く)",栽培スケジュール!$1:$1,0)),0),"") | ... AY32: =IF(ISNUMBER(SEARCH("s",AY11)),VLOOKUP(AY3,栽培スケジュール!$A:$AN,IFERROR(MATCH("経営費/月",栽培スケジュール!$1:$1,0),MATCH("経営費(減価償却費除く)",栽培スケジュール!$1:$1,0)),0),"")
B33: B | C33: =IF(ISNUMBER(SEARCH("s",C12)),VLOOKUP(C4,栽培スケジュール!$A:$AN,IFERROR(MATCH("経営費/月",栽培スケジュール!$1:$1,0),MATCH("経営費(減価償却費除く)",栽培スケジュール!$1:$1,0)),0),"") | D33: =IF(ISNUMBER(SEARCH("s",D12)),VLOOKUP(D4,栽培スケジュール!$A:$AN,IFERROR(MATCH("経営費/月",栽培スケジュール!$1:$1,0),MATCH("経営費(減価償却費除く)",栽培スケジュール!$1:$1,0)),0),"") | E33: =IF(ISNUMBER(SEARCH("s",E12)),VLOOKUP(E4,栽培スケジュール!$A:$AN,IFERROR(MATCH("経営費/月",栽培スケジュール!$1:$1,0),MATCH("経営費(減価償却費除く)",栽培スケジュール!$1:$1,0)),0),"") | F33: =IF(ISNUMBER(SEARCH("s",F12)),VLOOKUP(F4,栽培スケジュール!$A:$AN,IFERROR(MATCH("経営費/月",栽培スケジュール!$1:$1,0),MATCH("経営費(減価償却費除く)",栽培スケジュール!$1:$1,0)),0),"") | G33: =IF(ISNUMBER(SEARCH("s",G12)),VLOOKUP(G4,栽培スケジュール!$A:$AN,IFERROR(MATCH("経営費/月",栽培スケジュール!$1:$1,0),MATCH("経営費(減価償却費除く)",栽培スケジュール!$1:$1,0)),0),"") -> 693 | H33: =IF(ISNUMBER(SEARCH("s",H12)),VLOOKUP(H4,栽培スケジュール!$A:$AN,IFERROR(MATCH("経営費/月",栽培スケジュール!$1:$1,0),MATCH("経営費(減価償却費除く)",栽培スケジュール!$1:$1,0)),0),"") | I33: =IF(ISNUMBER(SEARCH("s",I12)),VLOOKUP(I4,栽培スケジュール!$A:$AN,IFERROR(MATCH("経営費/月",栽培スケジュール!$1:$1,0),MATCH("経営費(減価償却費除く)",栽培スケジュール!$1:$1,0)),0),"") | J33: =IF(ISNUMBER(SEARCH("s",J12)),VLOOKUP(J4,栽培スケジュール!$A:$AN,IFERROR(MATCH("経営費/月",栽培スケジュール!$1:$1,0),MATCH("経営費(減価償却費除く)",栽培スケジュール!$1:$1,0)),0),"") | ... AY33: =IF(ISNUMBER(SEARCH("s",AY12)),VLOOKUP(AY4,栽培スケジュール!$A:$AN,IFERROR(MATCH("経営費/月",栽培スケジュール!$1:$1,0),MATCH("経営費(減価償却費除く)",栽培スケジュール!$1:$1,0)),0),"")
B34: C | C34: =IF(ISNUMBER(SEARCH("s",C13)),VLOOKUP(C5,栽培スケジュール!$A:$AN,IFERROR(MATCH("経営費/月",栽培スケジュール!$1:$1,0),MATCH("経営費(減価償却費除く)",栽培スケジュール!$1:$1,0)),0),"") | D34: =IF(ISNUMBER(SEARCH("s",D13)),VLOOKUP(D5,栽培スケジュール!$A:$AN,IFERROR(MATCH("経営費/月",栽培スケジュール!$1:$1,0),MATCH("経営費(減価償却費除く)",栽培スケジュール!$1:$1,0)),0),"") | E34: =IF(ISNUMBER(SEARCH("s",E13)),VLOOKUP(E5,栽培スケジュール!$A:$AN,IFERROR(MATCH("経営費/月",栽培スケジュール!$1:$1,0),MATCH("経営費(減価償却費除く)",栽培スケジュール!$1:$1,0)),0),"") | F34: =IF(ISNUMBER(SEARCH("s",F13)),VLOOKUP(F5,栽培スケジュール!$A:$AN,IFERROR(MATCH("経営費/月",栽培スケジュール!$1:$1,0),MATCH("経営費(減価償却費除く)",栽培スケジュール!$1:$1,0)),0),"") | G34: =IF(ISNUMBER(SEARCH("s",G13)),VLOOKUP(G5,栽培スケジュール!$A:$AN,IFERROR(MATCH("経営費/月",栽培スケジュール!$1:$1,0),MATCH("経営費(減価償却費除く)",栽培スケジュール!$1:$1,0)),0),"") | H34: =IF(ISNUMBER(SEARCH("s",H13)),VLOOKUP(H5,栽培スケジュール!$A:$AN,IFERROR(MATCH("経営費/月",栽培スケジュール!$1:$1,0),MATCH("経営費(減価償却費除く)",栽培スケジュール!$1:$1,0)),0),"") | I34: =IF(ISNUMBER(SEARCH("s",I13)),VLOOKUP(I5,栽培スケジュール!$A:$AN,IFERROR(MATCH("経営費/月",栽培スケジュール!$1:$1,0),MATCH("経営費(減価償却費除く)",栽培スケジュール!$1:$1,0)),0),"") -> 693 | J34: =IF(ISNUMBER(SEARCH("s",J13)),VLOOKUP(J5,栽培スケジュール!$A:$AN,IFERROR(MATCH("経営費/月",栽培スケジュール!$1:$1,0),MATCH("経営費(減価償却費除く)",栽培スケジュール!$1:$1,0)),0),"") | ... AY34: =IF(ISNUMBER(SEARCH("s",AY13)),VLOOKUP(AY5,栽培スケジュール!$A:$AN,IFERROR(MATCH("経営費/月",栽培スケジュール!$1:$1,0),MATCH("経営費(減価償却費除く)",栽培スケジュール!$1:$1,0)),0),"")
B35: D | C35: =IF(ISNUMBER(SEARCH("s",C14)),VLOOKUP(C6,栽培スケジュール!$A:$AN,IFERROR(MATCH("経営費/月",栽培スケジュール!$1:$1,0),MATCH("経営費(減価償却費除く)",栽培スケジュール!$1:$1,0)),0),"") | D35: =IF(ISNUMBER(SEARCH("s",D14)),VLOOKUP(D6,栽培スケジュール!$A:$AN,IFERROR(MATCH("経営費/月",栽培スケジュール!$1:$1,0),MATCH("経営費(減価償却費除く)",栽培スケジュール!$1:$1,0)),0),"") -> 93.343454 | E35: =IF(ISNUMBER(SEARCH("s",E14)),VLOOKUP(E6,栽培スケジュール!$A:$AN,IFERROR(MATCH("経営費/月",栽培スケジュール!$1:$1,0),MATCH("経営費(減価償却費除く)",栽培スケジュール!$1:$1,0)),0),"") -> 93.343454 | F35: =IF(ISNUMBER(SEARCH("s",F14)),VLOOKUP(F6,栽培スケジュール!$A:$AN,IFERROR(MATCH("経営費/月",栽培スケジュール!$1:$1,0),MATCH("経営費(減価償却費除く)",栽培スケジュール!$1:$1,0)),0),"") | G35: =IF(ISNUMBER(SEARCH("s",G14)),VLOOKUP(G6,栽培スケジュール!$A:$AN,IFERROR(MATCH("経営費/月",栽培スケジュール!$1:$1,0),MATCH("経営費(減価償却費除く)",栽培スケジュール!$1:$1,0)),0),"") | H35: =IF(ISNUMBER(SEARCH("s",H14)),VLOOKUP(H6,栽培スケジュール!$A:$AN,IFERROR(MATCH("経営費/月",栽培スケジュール!$1:$1,0),MATCH("経営費(減価償却費除く)",栽培スケジュール!$1:$1,0)),0),"") | I35: =IF(ISNUMBER(SEARCH("s",I14)),VLOOKUP(I6,栽培スケジュール!$A:$AN,IFERROR(MATCH("経営費/月",栽培スケジュール!$1:$1,0),MATCH("経営費(減価償却費除く)",栽培スケジュール!$1:$1,0)),0),"") | J35: =IF(ISNUMBER(SEARCH("s",J14)),VLOOKUP(J6,栽培スケジュール!$A:$AN,IFERROR(MATCH("経営費/月",栽培スケジュール!$1:$1,0),MATCH("経営費(減価償却費除く)",栽培スケジュール!$1:$1,0)),0),"") | ... AY35: =IF(ISNUMBER(SEARCH("s",AY14)),VLOOKUP(AY6,栽培スケジュール!$A:$AN,IFERROR(MATCH("経営費/月",栽培スケジュール!$1:$1,0),MATCH("経営費(減価償却費除く)",栽培スケジュール!$1:$1,0)),0),"")
B36: 所得 | C36: =C26-C31 -> 0 | D36: =D26-D31 -> -93.343454 | E36: =E26-E31 -> -280.03036 | F36: =F26-F31 -> 0 | G36: =G26-G31 -> -298.31309 | H36: =H26-H31 -> 394.68691 | I36: =I26-I31 -> -143 | J36: =J26-J31 -> 550 | ... AY36: =AY26-AY31 -> 0
A38: 農地賃借の場合
A39: <簡易PL> | F39: 単位：千円
B40: FY | C40: 0 | D40: 1 | E40: 2 | F40: 3
B41: 粗収益 | C41: =SUM(C26:N26) -> 3388.2908 | D41: =SUM(O26:Z26) -> 4542.8594 | E41: =SUM(AA26:AL26) -> 4664.8666 | F41: =SUM(AM26:AX26) -> 4538.6294
B42: 直接経営費 | C42: =SUM(C31:N31)+VLOOKUP("annual_rent_thousand_yen",固定資産!$A:$B,2,FALSE) -> 2874.7577 | D42: =SUM(O31:Z31)+VLOOKUP("annual_rent_thousand_yen",固定資産!$A:$B,2,FALSE) -> 2678.3348 | E42: =SUM(AA31:AL31)+VLOOKUP("annual_rent_thousand_yen",固定資産!$A:$B,2,FALSE) -> 2637.3407 | F42: =SUM(AM31:AX31)+VLOOKUP("annual_rent_thousand_yen",固定資産!$A:$B,2,FALSE) -> 1966.5338
B43: 減価償却費 | C43: =VLOOKUP("annual_depreciation",固定資産!$A:$B,2,FALSE) -> 1347.9087 | D43: =VLOOKUP("annual_depreciation",固定資産!$A:$B,2,FALSE) -> 1347.9087 | E43: =VLOOKUP("annual_depreciation",固定資産!$A:$B,2,FALSE) -> 1347.9087 | F43: =VLOOKUP("annual_depreciation",固定資産!$A:$B,2,FALSE) -> 1347.9087
...
